<?xml version="1.0"?>
<robot xmlns:xacro="http://www.ros.org/wiki/xacro" >

    <xacro:include filename="inertial_macros.xacro"/>

    <!-- MATERIALS -->
    
    <material name="white">
        <color rgba="1 1 1 1"/>
    </material>

    <material name="orange">
        <color rgba="1 0.3 0.1 1"/>
    </material>

    <material name="blue">
        <color rgba="0.2 0.2 1 1"/>
    </material>

    <material name="black">
        <color rgba="0 0 0 1"/>
    </material>

    <material name="red">
        <color rgba="1 0 0 1"/>
    </material>

    <!-- BASE LINK -->

    <link name="base_link">
    
    </link>

    <!-- BASE FOOTPRINT LINK -->
    <joint name="base_footprint_joint" type="fixed">
        <parent link="base_link"/>
        <child link="base_footprint"/>
        <origin xyz="0 0 0" rpy="0 0 0"/>
    </joint>

    <link name="base_footprint">
    
    </link>

    <!-- CHASSIS LINK -->

    <joint name="chassis_joint" type="fixed">
        <parent link="base_link"/>
        <child link="chassis"/>
        <origin xyz="0 0 0"/>
    </joint>

    <link name="chassis">
        <visual>
            <!-- <origin xyz="0 0 0.15375"/> -->
            <origin xyz="0 0 0.185"/>
            <geometry>
                <box size="0.565 0.355 0.29"/>
            </geometry>
            <material name="white"/>
        </visual>
        <collision>
            <origin xyz="0 0 0.15375"/>
            <geometry>
                <box size="0.565 0.355 0.29"/>
            </geometry>
        </collision>
        <xacro:inertial_box mass="0.5" x="0.565" y="0.355" z="0.29">
            <origin xyz="0 0 0.15375" rpy="0 0 0"/>
        </xacro:inertial_box>
    </link>

    <gazebo reference="chassis">
        <material>Gazebo/White</material>
    </gazebo>

    <!-- FOR NOW NO FRICTION -->
    <!-- LEFT CASTER WHEEL LINK -->
    <joint name="left_caster_wheel_joint" type="fixed">
        <parent link="chassis"/>
        <child link="left_caster_wheel"/>
        <origin xyz="0.1925 0.1025 0.025"/>
    </joint>

    <link name="left_caster_wheel">
        <visual>
            <geometry>
                <sphere radius="0.025"/>
            </geometry>
            <material name="black"/>
        </visual>
    </link>

    <gazebo reference="left_caster_wheel">
        <material>Gazebo/Black</material>
        <mu1 value="0.01"/>
        <mu2 value="0.01"/>
    </gazebo>

    <!-- RIGHT CASTER WHEEL LINK -->
    <joint name="right_caster_wheel_joint" type="fixed">
        <parent link="chassis"/>
        <child link="right_caster_wheel"/>
        <origin xyz="0.1925 -0.1025 0.025"/>
    </joint>

    <link name="right_caster_wheel">
        <visual>
            <geometry>
                <sphere radius="0.025"/>
            </geometry>
            <material name="black"/>
        </visual>
    </link>

    <gazebo reference="right_caster_wheel">
        <material>Gazebo/Black</material>
        <mu1 value="0.01"/>
        <mu2 value="0.01"/>
    </gazebo>

    <!-- LEFT BACK WHEEL LINK-->

    <joint name="left_back_wheel_joint" type="continuous">
        <parent link="base_link"/>
        <child link="left_back_wheel"/>
        <origin xyz="-0.1675 0.19 0.0625" rpy="-${pi/2} 0 0"/>
        <axis xyz="0 0 1"/>
    </joint>

    <link name="left_back_wheel">
        <visual>
            <geometry>
                <cylinder radius="0.0625" length="0.025"/>
            </geometry>
            <material name="blue"/>
        </visual>
        <collision>
            <geometry>
                <cylinder radius="0.0625" length="0.025"/>
            </geometry>
        </collision>
        <xacro:inertial_cylinder mass="0.1" length="0.0625" radius="0.025">
            <origin xyz="0 0 0" rpy="0 0 0"/>
        </xacro:inertial_cylinder>
    </link>

    <gazebo reference="left_back_wheel">
        <material>Gazebo/Blue</material>
    </gazebo>

    <!-- RIGHT BACK WHEEL LINK-->

    <joint name="right_back_wheel_joint" type="continuous">
        <parent link="base_link"/>
        <child link="right_back_wheel"/>
        <origin xyz="-0.1675 -0.19 0.0625" rpy="${pi/2} 0 0"/>
        <axis xyz="0 0 -1"/>
    </joint>

    <link name="right_back_wheel">
        <visual>
            <geometry>
                <cylinder radius="0.0625" length="0.025"/>
            </geometry>
            <material name="blue"/>
        </visual>
        <collision>
            <geometry>
                <cylinder radius="0.0625" length="0.025"/>
            </geometry>
        </collision>
        <xacro:inertial_cylinder mass="0.1" length="0.0625" radius="0.025">
            <origin xyz="0 0 0" rpy="0 0 0"/>
        </xacro:inertial_cylinder>
    </link>

    <gazebo reference="right_back_wheel">
        <material>Gazebo/Blue</material>
    </gazebo>

</robot>